Workbook

Sheet Аркуш1
A1: БАТАЛЬЙОН | B1: ПІДРОЗДІЛ | C1: Штатна кількість О/C (100%) | D1: Кількість за списком | E1: Наявність | F1: О/С % | G1: О/с на виконанні бойового завдання | J1: Резерв о/с кома-ндира полку | K1: БЗВП
G3: На виконанні б/з | H3: Резерв згідно графіку заміни | I3: Резерв о/с викона-ння бойових завдань | K3: 01.07 - 07.07 | L3: 08.07 - 14.07 | M3: 16.07 - 22.07 | N3: 22.07 - 31.07
A4: 1 ШБ | B4: Управління | C4: 8 | D4: 7 | F4: =D4/C4 -> 0.875 | G4: 0 | H4: 0 | I4: 0 | J4: 0 | K4: 0 | L4: 0 | M4: 0 | N4: 0
B5: Штаб | C5: 20 | D5: 14 | F5: =D5/C5 -> 0.7 | G5: 0 | H5: 0 | I5: 0 | J5: 0 | K5: 0 | L5: 0 | M5: 0 | N5: 0
B6: 1 штурмова рота | C6: 166 | D6: 159 | F6: =D6/C6 -> 0.95783133 | G6: 12 | H6: 0 | I6: 0 | J6: 0 | K6: 0 | L6: 0 | M6: 1 | N6: 0
B7: 2 штурмова рота | C7: 166 | D7: 160 | F7: =D7/C7 -> 0.96385542 | G7: 11 | H7: 0 | I7: 0 | J7: 0 | K7: 0 | L7: 0 | M7: 12 | N7: 0
B8: 3 штурмова рота | C8: 157 | D8: 154 | F8: =D8/C8 -> 0.98089172 | G8: 10 | H8: 0 | I8: 0 | J8: 0 | K8: 0 | L8: 0 | M8: 10 | N8: 0
B9: Взвод зв'язку | C9: 20 | D9: 19 | F9: =D9/C9 -> 0.95 | G9: 3 | H9: 0 | I9: 0 | J9: 0 | K9: 0 | L9: 0 | M9: 0 | N9: 0
B10: ВМЗ | C10: 21 | D10: 21 | F10: =D10/C10 -> 1 | G10: 0 | H10: 0 | I10: 0 | J10: 0 | K10: 0 | L10: 0 | M10: 0 | N10: 0
B11: Взвод перехоплювачів БПЛА | C11: 24 | D11: 23 | F11: =D11/C11 -> 0.95833333 | G11: 0 | H11: 0 | I11: 0 | J11: 0 | K11: 0 | L11: 0 | M11: 0 | N11: 0
B12: ВТЗ | C12: 17 | D12: 17 | F12: =D12/C12 -> 1 | G12: 0 | H12: 0 | I12: 0 | J12: 0 | K12: 0 | L12: 0 | M12: 0 | N12: 0
B13: Відділення РЕБ | C13: 12 | D13: 12 | F13: =D13/C13 -> 1 | G13: 0 | H13: 0 | I13: 0 | J13: 0 | K13: 0 | L13: 0 | M13: 0 | N13: 0
B14: Група безпілотних систем | C14: 5 | D14: 4 | F14: =D14/C14 -> 0.8 | G14: 0 | H14: 0 | I14: 0 | J14: 0 | K14: 0 | L14: 0 | M14: 0 | N14: 0
B15: Група ОВГП | C15: 2 | D15: 1 | F15: =D15/C15 -> 0.5 | G15: 0 | H15: 0 | I15: 0 | J15: 0 | K15: 0 | L15: 0 | M15: 0 | N15: 0
B16: Знітно - ракетний взвод | C16: 0 | D16: 0 | F16: 0 | G16: 0 | H16: 0 | I16: 0 | J16: 0 | K16: 0 | L16: 0 | M16: 0 | N16: 0
B17: ІСВ | C17: 26 | D17: 25 | F17: =D17/C17 -> 0.96153846 | G17: 0 | H17: 0 | I17: 0 | J17: 0 | K17: 0 | L17: 0 | M17: 0 | N17: 0
B18: Мінометна батарея | C18: 83 | D18: 80 | F18: =D18/C18 -> 0.96385542 | G18: 0 | H18: 0 | I18: 0 | J18: 0 | K18: 0 | L18: 0 | M18: 0 | N18: 0
B19: Розвідувальний взвод | C19: 32 | D19: 30 | F19: =D19/C19 -> 0.9375 | G19: 4 | H19: 0 | I19: 0 | J19: 0 | K19: 0 | L19: 0 | M19: 9 | N19: 0
B20: Рота безпілотних авіаційних комплексів | C20: 87 | D20: 82 | F20: =D20/C20 -> 0.94252874 | G20: 35 | H20: 0 | I20: 0 | J20: 0 | K20: 0 | L20: 0 | M20: 3 | N20: 0
B21: Рота вогневої підтримки | C21: 127 | D21: 120 | F21: =D21/C21 -> 0.94488189 | G21: 13 | H21: 0 | I21: 0 | J21: 0 | K21: 0 | L21: 0 | M21: 3 | N21: 6
B22: Медичний пункт | C22: 21 | D22: 16 | F22: =D22/C22 -> 0.76190476 | G22: 2 | H22: 0 | I22: 0 | J22: 0 | K22: 0 | L22: 0 | M22: 0 | N22: 0
A23: Всього: | C23: =SUM(C4:C22) -> 994 | D23: =SUM(D4:D22) -> 944 | F23: =D23/C23 -> 0.94969819 | G23: =SUM(G4:G22) -> 90 | H23: 0 | I23: 0 | J23: 0 | K23: 0 | L23: 0 | M23: =SUM(M4:M22) -> 38 | N23: =SUM(N4:N22) -> 6
A24: 2 ШБ | B24: Управління | C24: 8 | D24: 7 | F24: =D24/C24 -> 0.875 | G24: 0 | H24: 0 | I24: 0 | J24: 0 | K24: 0 | L24: 0 | M24: 0 | N24: 0
B25: Штаб | C25: 20 | D25: 14 | F25: =D25/C25 -> 0.7 | G25: 0 | H25: 0 | I25: 0 | J25: 0 | K25: 0 | L25: 0 | M25: 0 | N25: 0
B26: 1 штурмова рота | C26: 166 | D26: 160 | F26: =D26/C26 -> 0.96385542 | G26: 16 | H26: 0 | I26: 1 | J26: 0 | K26: 0 | L26: 0 | M26: 0 | N26: 8
B27: 2 штурмова рота | C27: 166 | D27: 160 | F27: =D27/C27 -> 0.96385542 | G27: 10 | H27: 0 | I27: 3 | J27: 0 | K27: 0 | L27: 0 | M27: 0 | N27: 25
B28: 3 штурмова рота | C28: 157 | D28: 159 | F28: =D28/C28 -> 1.0127389 | G28: 16 | H28: 0 | I28: 3 | J28: 0 | K28: 0 | L28: 0 | M28: 0 | N28: 5
B29: Взвод зв'язку | C29: 20 | D29: 19 | F29: =D29/C29 -> 0.95 | G29: 4 | H29: 0 | I29: 0 | J29: 0 | K29: 0 | L29: 0 | M29: 0 | N29: 0
B30: ВМЗ | C30: 21 | D30: 21 | F30: =D30/C30 -> 1 | G30: 0 | H30: 0 | I30: 0 | J30: 0 | K30: 0 | L30: 0 | M30: 0 | N30: 1
B31: Взвод перехоплювачів БПЛА | C31: 24 | D31: 22 | F31: =D31/C31 -> 0.91666667 | G31: 7 | H31: 0 | I31: 0 | J31: 0 | K31: 0 | L31: 0 | M31: 0 | N31: 0
B32: ВТЗ | C32: 17 | D32: 17 | F32: =D32/C32 -> 1 | G32: 0 | H32: 0 | I32: 0 | J32: 0 | K32: 0 | L32: 0 | M32: 0 | N32: 0
B33: Відділення РЕБ | C33: 12 | D33: 12 | F33: =D33/C33 -> 1 | G33: 6 | H33: 0 | I33: 0 | J33: 0 | K33: 0 | L33: 0 | M33: 0 | N33: 0
B34: Група безпілотних систем | C34: 5 | D34: 2 | F34: =D34/C34 -> 0.4 | G34: 0 | H34: 0 | I34: 0 | J34: 0 | K34: 0 | L34: 0 | M34: 0 | N34: 0
B35: Група ОВГП | C35: 2 | D35: 1 | F35: =D35/C35 -> 0.5 | H35: 0 | I35: 0 | J35: 0 | K35: 0 | L35: 0 | M35: 0 | N35: 0
B36: ІСВ | C36: 26 | D36: 30 | F36: =D36/C36 -> 1.1538462 | G36: 0 | H36: 0 | I36: 0 | J36: 0 | K36: 0 | L36: 0 | M36: 0 | N36: 0
B37: Мінометна батарея | C37: 83 | D37: 80 | F37: =D37/C37 -> 0.96385542 | G37: 3 | H37: 0 | I37: 0 | J37: 0 | K37: 0 | L37: 0 | M37: 0 | N37: 0
B38: Розвідувальний взвод | C38: 32 | D38: 29 | F38: =D38/C38 -> 0.90625 | G38: 0 | H38: 0 | J38: 0 | K38: 0 | L38: 0 | M38: 0 | N38: 0
B39: Рота безпілотних авіаційних комплексів | C39: 87 | D39: 83 | F39: =D39/C39 -> 0.95402299 | G39: 44 | H39: 0 | I39: 0 | J39: 0 | K39: 0 | L39: 0 | M39: 0 | N39: 5
B40: Рота вогневої підтримки | C40: 127 | D40: 123 | F40: =D40/C40 -> 0.96850394 | G40: 11 | H40: 0 | I40: 2 | J40: 0 | K40: 0 | L40: 0 | M40: 0 | N40: 4
B41: Медичний пункт | C41: 21 | D41: 19 | F41: =D41/C41 -> 0.9047619 | G41: 1 | H41: 0 | I41: 0 | J41: 0 | K41: 0 | L41: 0 | M41: 0 | N41: 0
...
